<?xml version="1.0" ?>
<robot name="arm" xmlns:xacro="http://www.ros.org/wiki/xacro">

<xacro:include filename="$(find arm_description)/urdf/materials.xacro" />
<xacro:include filename="$(find arm_description)/urdf/arm.trans" />
<xacro:include filename="$(find arm_description)/urdf/arm.gazebo" />

<link name="world"></link>

<link name="base_link">
  <inertial>
    <origin xyz="1.5583310805039967e-06 0.058762918800636485 0.07348515003124369" rpy="0 0 0"/>
    <mass value="23.94526398257078"/>
    <inertia ixx="0.309271" iyy="0.165271" izz="0.320305" ixy="-4.3e-05" iyz="0.028403" ixz="3.7e-05"/>
  </inertial>
  <visual>
    <origin xyz="0 0 0" rpy="0 0 0"/>
    <geometry>
      <mesh filename="package://arm_description/meshes/base_link.stl" scale="0.001 0.001 0.001"/>
    </geometry>
    <material name="black"/>
  </visual>
  <collision>
    <origin xyz="0 0 0" rpy="0 0 0"/>
    <geometry>
      <mesh filename="package://arm_description/meshes/base_link.stl" scale="0.001 0.001 0.001"/>
    </geometry>
  </collision>
</link>

<link name="u_link_1">
  <inertial>
    <origin xyz="-0.018413834929736937 0.015508900349939838 0.05445256775884938" rpy="0 0 0"/>
    <mass value="3.293756000284771"/>
    <inertia ixx="0.018017" iyy="0.027282" izz="0.02984" ixy="0.00444" iyz="0.001142" ixz="-0.001519"/>
  </inertial>
  <visual>
    <origin xyz="0.0 0.0 -0.16" rpy="0 0 0"/>
    <geometry>
      <mesh filename="package://arm_description/meshes/u_link_1.stl" scale="0.001 0.001 0.001"/>
    </geometry>
    <material name="silver"/>
  </visual>
  <collision>
    <origin xyz="0.0 0.0 -0.16" rpy="0 0 0"/>
    <geometry>
      <mesh filename="package://arm_description/meshes/u_link_1.stl" scale="0.001 0.001 0.001"/>
    </geometry>
  </collision>
</link>

<link name="shoulder_link_1">
  <inertial>
    <origin xyz="-0.05987555052737282 0.0016661954030487006 0.08072308228169744" rpy="0 0 0"/>
    <mass value="1.3689764158821631"/>
    <inertia ixx="0.015585" iyy="0.015646" izz="0.003803" ixy="5e-06" iyz="0.000178" ixz="8.2e-05"/>
  </inertial>
  <visual>
    <origin xyz="-0.062802 -0.0 -0.267" rpy="0 0 0"/>
    <geometry>
      <mesh filename="package://arm_description/meshes/shoulder_link_1.stl" scale="0.001 0.001 0.001"/>
    </geometry>
    <material name="silver"/>
  </visual>
  <collision>
    <origin xyz="-0.062802 -0.0 -0.267" rpy="0 0 0"/>
    <geometry>
      <mesh filename="package://arm_description/meshes/shoulder_link_1.stl" scale="0.001 0.001 0.001"/>
    </geometry>
  </collision>
</link>

<link name="shoulder_cap2_1">
  <inertial>
    <origin xyz="0.020508754108554156 1.350999646597173e-06 -0.03893169780530764" rpy="0 0 0"/>
    <mass value="0.04651284138238731"/>
    <inertia ixx="0.00015" iyy="0.000129" izz="3.2e-05" ixy="-0.0" iyz="0.0" ixz="-1e-06"/>
  </inertial>
  <visual>
    <origin xyz="-0.045822 -0.0 -0.498806" rpy="0 0 0"/>
    <geometry>
      <mesh filename="package://arm_description/meshes/shoulder_cap2_1.stl" scale="0.001 0.001 0.001"/>
    </geometry>
    <material name="blue"/>
  </visual>
  <collision>
    <origin xyz="-0.045822 -0.0 -0.498806" rpy="0 0 0"/>
    <geometry>
      <mesh filename="package://arm_description/meshes/shoulder_cap2_1.stl" scale="0.001 0.001 0.001"/>
    </geometry>
  </collision>
</link>

<link name="shoulder_cap1_1">
  <inertial>
    <origin xyz="-0.020509387614893966 1.3445240348147222e-06 -0.03893178263179736" rpy="0 0 0"/>
    <mass value="0.046512791011032124"/>
    <inertia ixx="0.00015" iyy="0.000129" izz="3.2e-05" ixy="0.0" iyz="0.0" ixz="1e-06"/>
  </inertial>
  <visual>
    <origin xyz="0.044178 -0.0 -0.498806" rpy="0 0 0"/>
    <geometry>
      <mesh filename="package://arm_description/meshes/shoulder_cap1_1.stl" scale="0.001 0.001 0.001"/>
    </geometry>
    <material name="blue"/>
  </visual>
  <collision>
    <origin xyz="0.044178 -0.0 -0.498806" rpy="0 0 0"/>
    <geometry>
      <mesh filename="package://arm_description/meshes/shoulder_cap1_1.stl" scale="0.001 0.001 0.001"/>
    </geometry>
  </collision>
</link>

<link name="elbow_link_1">
  <inertial>
    <origin xyz="-0.03492194072409198 2.6143098979566015e-07 0.0876301764882011" rpy="0 0 0"/>
    <mass value="0.7470783717856831"/>
    <inertia ixx="0.005387" iyy="0.00546" izz="0.001108" ixy="0.0" iyz="0.0" ixz="-3e-06"/>
  </inertial>
  <visual>
    <origin xyz="-0.035822 -0.0 -0.498806" rpy="0 0 0"/>
    <geometry>
      <mesh filename="package://arm_description/meshes/elbow_link_1.stl" scale="0.001 0.001 0.001"/>
    </geometry>
    <material name="silver"/>
  </visual>
  <collision>
    <origin xyz="-0.035822 -0.0 -0.498806" rpy="0 0 0"/>
    <geometry>
      <mesh filename="package://arm_description/meshes/elbow_link_1.stl" scale="0.001 0.001 0.001"/>
    </geometry>
  </collision>
</link>

<link name="elbow_cap2_1">
  <inertial>
    <origin xyz="0.02148739183855515 2.9217825477518897e-07 -0.040789570146649634" rpy="0 0 0"/>
    <mass value="0.043629377048852905"/>
    <inertia ixx="0.00011" iyy="9.8e-05" izz="2e-05" ixy="0.0" iyz="-0.0" ixz="-1e-06"/>
  </inertial>
  <visual>
    <origin xyz="-0.035822 -0.0 -0.703806" rpy="0 0 0"/>
    <geometry>
      <mesh filename="package://arm_description/meshes/elbow_cap2_1.stl" scale="0.001 0.001 0.001"/>
    </geometry>
    <material name="blue"/>
  </visual>
  <collision>
    <origin xyz="-0.035822 -0.0 -0.703806" rpy="0 0 0"/>
    <geometry>
      <mesh filename="package://arm_description/meshes/elbow_cap2_1.stl" scale="0.001 0.001 0.001"/>
    </geometry>
  </collision>
</link>

<link name="elbow_cap1_1">
  <inertial>
    <origin xyz="-0.021488033545251868 2.6011906745381255e-07 -0.04078956928847666" rpy="0 0 0"/>
    <mass value="0.04362924121179823"/>
    <inertia ixx="0.00011" iyy="9.8e-05" izz="2e-05" ixy="-0.0" iyz="-0.0" ixz="1e-06"/>
  </inertial>
  <visual>
    <origin xyz="0.034178 -0.0 -0.703806" rpy="0 0 0"/>
    <geometry>
      <mesh filename="package://arm_description/meshes/elbow_cap1_1.stl" scale="0.001 0.001 0.001"/>
    </geometry>
    <material name="blue"/>
  </visual>
  <collision>
    <origin xyz="0.034178 -0.0 -0.703806" rpy="0 0 0"/>
    <geometry>
      <mesh filename="package://arm_description/meshes/elbow_cap1_1.stl" scale="0.001 0.001 0.001"/>
    </geometry>
  </collision>
</link>

<link name="wrist_1">
  <inertial>
    <origin xyz="0.02596103508467108 0.0019201483715676508 0.02309591219585605" rpy="0 0 0"/>
    <mass value="0.4164389227013165"/>
    <inertia ixx="0.001358" iyy="0.001208" izz="0.000403" ixy="-0.0" iyz="-4.3e-05" ixz="-0.0"/>
  </inertial>
  <visual>
    <origin xyz="0.025178 -0.0 -0.703806" rpy="0 0 0"/>
    <geometry>
      <mesh filename="package://arm_description/meshes/wrist_1.stl" scale="0.001 0.001 0.001"/>
    </geometry>
    <material name="silver"/>
  </visual>
  <collision>
    <origin xyz="0.025178 -0.0 -0.703806" rpy="0 0 0"/>
    <geometry>
      <mesh filename="package://arm_description/meshes/wrist_1.stl" scale="0.001 0.001 0.001"/>
    </geometry>
  </collision>
</link>

<link name="tool_1">
  <inertial>
    <origin xyz="-0.00014605030879303715 5.174310709705251e-05 0.02419632782425385" rpy="0 0 0"/>
    <mass value="0.23133664156510922"/>
    <inertia ixx="7.2e-05" iyy="7.6e-05" izz="3.1e-05" ixy="-0.0" iyz="0.0" ixz="-1e-06"/>
  </inertial>
  <visual>
    <origin xyz="-0.000822 0.006285 -0.806946" rpy="0 0 0"/>
    <geometry>
      <mesh filename="package://arm_description/meshes/tool_1.stl" scale="0.001 0.001 0.001"/>
    </geometry>
    <material name="black"/>
  </visual>
  <collision>
    <origin xyz="-0.000822 0.006285 -0.806946" rpy="0 0 0"/>
    <geometry>
      <mesh filename="package://arm_description/meshes/tool_1.stl" scale="0.001 0.001 0.001"/>
    </geometry>
  </collision>
</link>

<link name="f1_1">
  <inertial>
    <origin xyz="-9.368555315126571e-05 -0.01099973874330657 0.0038035551000972223" rpy="0 0 0"/>
    <mass value="0.018138182275468137"/>
    <inertia ixx="4e-06" iyy="4e-06" izz="0.0" ixy="-0.0" iyz="0.0" ixz="0.0"/>
  </inertial>
  <visual>
    <origin xyz="0.010615 -0.004715 -0.858383" rpy="0 0 0"/>
    <geometry>
      <mesh filename="package://arm_description/meshes/f1_1.stl" scale="0.001 0.001 0.001"/>
    </geometry>
    <material name="silver"/>
  </visual>
  <collision>
    <origin xyz="0.010615 -0.004715 -0.858383" rpy="0 0 0"/>
    <geometry>
      <mesh filename="package://arm_description/meshes/f1_1.stl" scale="0.001 0.001 0.001"/>
    </geometry>
  </collision>
</link>

<link name="f2_1">
  <inertial>
    <origin xyz="9.305800941864818e-05 -0.010999738743365347 0.0038035551000977774" rpy="0 0 0"/>
    <mass value="0.018138182275468456"/>
    <inertia ixx="4e-06" iyy="4e-06" izz="0.0" ixy="-0.0" iyz="0.0" ixz="-0.0"/>
  </inertial>
  <visual>
    <origin xyz="-0.012259 -0.004715 -0.858383" rpy="0 0 0"/>
    <geometry>
      <mesh filename="package://arm_description/meshes/f2_1.stl" scale="0.001 0.001 0.001"/>
    </geometry>
    <material name="silver"/>
  </visual>
  <collision>
    <origin xyz="-0.012259 -0.004715 -0.858383" rpy="0 0 0"/>
    <geometry>
      <mesh filename="package://arm_description/meshes/f2_1.stl" scale="0.001 0.001 0.001"/>
    </geometry>
  </collision>
</link>

<joint name="just" type="fixed">
  <parent link="world"/>
  <child link="base_link"/>
  <origin xyz="0.0 0.0 0.0" rpy="0.0 0.0 0.0"/>
</joint>


<joint name="base_to_ulink" type="revolute">
  <origin xyz="0.0 0.0 0.16" rpy="0 0 0"/>
  <parent link="base_link"/>
  <child link="u_link_1"/>
  <axis xyz="0.0 0.0 -1.0"/>
  <limit upper="2.530727" lower="-2.530727" effort="1" velocity="10"/>
</joint>

<joint name="ulink_to_shoulderlink" type="revolute">
  <origin xyz="0.062802 0.0 0.107" rpy="0 0 0"/>
  <parent link="u_link_1"/>
  <child link="shoulder_link_1"/>
  <axis xyz="1.0 0.0 0.0"/>
  <limit upper="1.570796" lower="-1.570796" effort="1" velocity="10"/>
</joint>

<joint name="shouldercap2" type="fixed">
  <origin xyz="-0.01698 0.0 0.231806" rpy="0 0 0"/>
  <parent link="shoulder_link_1"/>
  <child link="shoulder_cap2_1"/>
</joint>

<joint name="shouldercap1" type="fixed">
  <origin xyz="-0.10698 0.0 0.231806" rpy="0 0 0"/>
  <parent link="shoulder_link_1"/>
  <child link="shoulder_cap1_1"/>
</joint>

<joint name="shoulderlink_to_elbowlink" type="revolute">
  <origin xyz="-0.02698 0.0 0.231806" rpy="0 0 0"/>
  <parent link="shoulder_link_1"/>
  <child link="elbow_link_1"/>
  <axis xyz="1.0 0.0 0.0"/>
  <limit upper="1.745329" lower="-1.745329" effort="1" velocity="10"/>
</joint>

<joint name="elbowcap1" type="fixed">
  <origin xyz="0.0 0.0 0.205" rpy="0 0 0"/>
  <parent link="elbow_link_1"/>
  <child link="elbow_cap2_1"/>
</joint>

<joint name="elbowcap2" type="fixed">
  <origin xyz="-0.07 0.0 0.205" rpy="0 0 0"/>
  <parent link="elbow_link_1"/>
  <child link="elbow_cap1_1"/>
</joint>

<joint name="elbowlink_to_wristlink" type="revolute">
  <origin xyz="-0.061 0.0 0.205" rpy="0 0 0"/>
  <parent link="elbow_link_1"/>
  <child link="wrist_1"/>
  <axis xyz="-1.0 -0.0 -0.0"/>
  <limit upper="1.745329" lower="-1.745329" effort="1" velocity="10"/>
</joint>

<joint name="wristlink_to_toollink" type="continuous">
  <origin xyz="0.026 -0.006285 0.10314" rpy="0 0 0"/>
  <parent link="wrist_1"/>
  <child link="tool_1"/>
  <axis xyz="0.0 0.0 -1.0"/>
</joint>

<joint name="toolf1" type="revolute">
  <origin xyz="-0.011437 0.011 0.051437" rpy="0 0 0"/>
  <parent link="tool_1"/>
  <child link="f1_1"/>
  <axis xyz="0.0 -1.0 -0.0"/>
  <limit upper="0.261799" lower="0.0" effort="1" velocity="10"/>
</joint>

<joint name="toolf2" type="revolute">
  <origin xyz="0.011437 0.011 0.051437" rpy="0 0 0"/>
  <parent link="tool_1"/>
  <child link="f2_1"/>
  <axis xyz="0.0 -1.0 -0.0"/>
  <limit upper="0.0" lower="-0.261799" effort="1" velocity="10"/>
</joint>

<!-- <gazebo>
  <plugin filename="libgazebo_ros_control.so" name="gazebo_ros_control">
    <robotNamespace>/arm</robotNamespace>
    <robotSimType>gazebo_ros_control/DefaultRobotHWSim</robotSimType>
  </plugin>
</gazebo> -->

</robot>
